Workbook

Sheet Summary_Dashboard
A1: EXIUM MUPS - SR. / MIO AWARD CATALOGUE CHOICE SUMMARY
A4: Campaign Metric | B4: May 2026 | C4: June 2026 | D4: Total Combined
A5: Total Eligible Achievers | B5: =COUNTA(Award_May_2026!A2:A722) | C5: =COUNTA(Award_June_2026!A2:A821) | D5: =B5+C5
A6: Completed Selections | B6: =COUNTIF(Award_May_2026!Q2:Q722, "Complete") | C6: =COUNTIF(Award_June_2026!S2:S821, "Complete") | D6: =B6+C6
A7: Pending Selections | B7: =COUNTIF(Award_May_2026!Q2:Q722, "Not Started") | C7: =COUNTIF(Award_June_2026!S2:S821, "Not Started") | D7: =B7+C7
A8: Completion Rate (%) | B8: =IF(B5>0, B6/B5, 0) | C8: =IF(C5>0, C6/C5, 0) | D8: =IF(D5>0, D6/D5, 0)
A11: Voucher Brand | B11: May Count | C11: June Count | D11: Total Selected | E11: % Share
A12: Infinity Gift Voucher | B12: =COUNTIF(Award_May_2026!O2:O722, "*Infinity Gift Voucher*") | C12: =COUNTIF(Award_June_2026!Q2:Q821, "*Infinity Gift Voucher*") | D12: =B12+C12 | E12: =IF($D$6>0, D12/$D$6, 0)
A13: Apex Gift Voucher | B13: =COUNTIF(Award_May_2026!O2:O722, "*Apex Gift Voucher*") | C13: =COUNTIF(Award_June_2026!Q2:Q821, "*Apex Gift Voucher*") | D13: =B13+C13 | E13: =IF($D$6>0, D13/$D$6, 0)
A14: Bata Gift Voucher | B14: =COUNTIF(Award_May_2026!O2:O722, "*Bata Gift Voucher*") | C14: =COUNTIF(Award_June_2026!Q2:Q821, "*Bata Gift Voucher*") | D14: =B14+C14 | E14: =IF($D$6>0, D14/$D$6, 0)
A15: Aarong Gift Voucher | B15: =COUNTIF(Award_May_2026!O2:O722, "*Aarong Gift Voucher*") | C15: =COUNTIF(Award_June_2026!Q2:Q821, "*Aarong Gift Voucher*") | D15: =B15+C15 | E15: =IF($D$6>0, D15/$D$6, 0)
A16: Best Buy Gift Voucher | B16: =COUNTIF(Award_May_2026!O2:O722, "*Best Buy Gift Voucher*") | C16: =COUNTIF(Award_June_2026!Q2:Q821, "*Best Buy Gift Voucher*") | D16: =B16+C16 | E16: =IF($D$6>0, D16/$D$6, 0)
A17: Cats Eye Gift Voucher | B17: =COUNTIF(Award_May_2026!O2:O722, "*Cats Eye Gift Voucher*") | C17: =COUNTIF(Award_June_2026!Q2:Q821, "*Cats Eye Gift Voucher*") | D17: =B17+C17 | E17: =IF($D$6>0, D17/$D$6, 0)

Sheet Award_May_2026
A1: SL | B1: Current Zone | C1: Current SAP Zone | D1: Current Region | E1: Current SAP Region | F1: Current Regional Head | G1: Current Area Code | H1: Current Area Name | I1: SAP MIO Code | J1: Sr./ MIO Name | K1: Designation | L1: No. of Rx | M1: Ach% | N1: Award Amount (BDT) | O1: Selected Voucher | P1: Submission Timestamp | Q1: Status | R1: Is Transferred | S1: Previous Area Code | T1: Previous Area Name | U1: Previous Region | V1: Previous Regional Head | W1: Previous Zone
A2: 1 | B2: Chattogram-C (GEN-A) | C2: 17032 | D2: Potiya GEN-A-1 | E2: 16172 | F2: Md. Majharul Islam | G2: 13027 | H2: Potiya-6 | I2: 6135 | J2: Mr. Md. Aminul Islam | K2: Medical Information Officer | L2: 499 | M2: 148.34611 | N2: 2000 | Q2: Not Started | R2: NO
A3: 2 | B3: Rajshahi (GEN-A) | C3: 17008 | D3: Rajshahi GEN-A-3 | E3: 16037 | F3: Fazlul Haque | G3: 12408 | H3: Bagha-1 | I3: 6060 | J3: Md. Ruhul Amin | K3: Medical Information Officer | L3: 460 | M3: 112.23667 | N3: 2000 | Q3: Not Started | R3: NO
A4: 3 | B4: Cumilla (GEN-A) | C4: 17027 | D4: Cumilla GEN-A-1 | E4: 16144 | F4: Md. Alamgir Hossain | G4: 10925 | H4: Cumilla (Racecourse) | I4: 2388 | J4: Md. Shafiqul Islam | K4: Sr. Medical Information Officer | L4: 451 | M4: 121.28502 | N4: 2000 | Q4: Not Started | R4: NO
A5: 4 | B5: Rajshahi (GEN-A) | C5: 17008 | D5: Patnitola GEN-A-1 | E5: 16038 | F5: Mr. Khondokar Mazharul Islam | G5: 14883 | H5: Porsha-1 | I5: 2605 | J5: Nandan Kumar Roy | K5: Sr. Medical Information Officer | L5: 426 | M5: 120.00981 | N5: 2000 | Q5: Not Started | R5: YES | S5: 10265 | T5: Sapahar-1 | U5: Patnitola GEN-A-1 | V5: Mr. Khondokar Mazharul Islam | W5: Rajshahi
A6: 5 | B6: Chattogram-A (GEN-A) | C6: 17031 | D6: Chattogram GEN-A-9 | E6: 16157 | F6: Mr. Md. Zahidul Islam | G6: 11029 | H6: CTG (Navy Gate)-2 | I6: 1182 | J6: Md. Abdul Mannan Sarker | K6: Sr. Medical Information Officer | L6: 414 | M6: 146.4334 | N6: 2000 | Q6: Not Started | R6: NO
A7: 6 | B7: Chattogram-C (GEN-A) | C7: 17032 | D7: Chattogram GEN-A-1 | E7: 16169 | F7: Mr. Md. Salimujjaman | G7: 11109 | H7: CTG (Metropolitan Hosp.)-2 | I7: 1518 | J7: Suel Rana | K7: Medical Information Officer | L7: 409 | M7: 130.45594 | N7: 2000 | Q7: Not Started | R7: NO
A8: 7 | B8: Chattogram-C (GEN-A) | C8: 17032 | D8: Chattogram GEN-A-1 | E8: 16169 | F8: Mr. Md. Salimujjaman | G8: 11108 | H8: CTG (Metropolitan Hosp.)-1 | I8: 5012 | J8: Mr. Md. Saddam Hossain | K8: Sr. Medical Information Officer | L8: 403 | M8: 135.14409 | N8: 2000 | Q8: Not Started | R8: NO
A9: 8 | B9: Dinajpur (GEN-A) | C9: 17006 | D9: Joypurhat GEN-A | E9: 16027 | F9: Mr. Md. Asadujjaman | G9: 12907 | H9: Joypurhat-4 | I9: 6900 | J9: Mr. Muha. Miraz Jowarder | K9: Medical Information Officer | L9: 390 | M9: 105.09858 | N9: 2000 | Q9: Not Started | R9: NO
A10: 9 | B10: Uttara (GEN-A) | C10: 17021 | D10: Uttara GEN-A-3 | E10: 16112 | F10: Md. Asif Anam | G10: 14884 | H10: Uttara Adhunik-Ibn Sina | I10: 4161 | J10: Mr. Md. Ansarul Islam | K10: Medical Information Officer | L10: 380 | M10: 125.15396 | N10: 2000 | Q10: Not Started | R10: YES | S10: 12550 | T10: Potiya-5 | U10: Potiya GEN-A-1 | V10: Mr. Md. Rafiqul Islam | W10: Chattogram-C
A11: 10 | B11: Chattogram-C (GEN-A) | C11: 17032 | D11: Chattogram GEN-A-1 | E11: 16169 | F11: Mr. Md. Salimujjaman | G11: 11119 | H11: CTG (Lab Aid)-1 | I11: 6662 | J11: Mr. Md. Robel Mia | K11: Medical Information Officer | L11: 380 | M11: 112.05407 | N11: 2000 | Q11: Not Started | R11: NO
A12: 11 | B12: Mymensingh (GEN-A) | C12: 17024 | D12: Mymensingh GEN-A-3 | E12: 16127 | F12: Mr. Md. Ershad Ali | G12: 10822 | H12: MYM(Nexus Hosp.) | I12: 525 | J12: A. K. M. Shamsur Rahman | K12: Sr. Medical Information Officer | L12: 378 | M12: 117.21294 | N12: 2000 | Q12: Not Started | R12: NO
A13: 12 | B13: Faridpur (GEN-A) | C13: 17013 | D13: Bhanga GEN-A-1 | E13: 16067 | F13: Mr. Md. Zahid Hossain Khan | G13: 10449 | H13: Nogorkanda | I13: 1166 | J13: Md. Ibrahim Dhali | K13: Sr. Medical Information Officer | L13: 377 | M13: 103.17534 | N13: 1000 | Q13: Not Started | R13: NO
A14: 13 | B14: Rangpur (GEN-A) | C14: 17007 | D14: Mithapukur GEN-A-1 | E14: 16620 | F14: Mr. Amzad Hossain Mia | G14: 14712 | H14: Pirganj-3 (Gaibandha) | I14: 3651 | J14: Mr. Md. Manikuzzaman | K14: Medical Information Officer | L14: 377 | M14: 159.49583 | N14: 2000 | Q14: Not Started | R14: NO
A15: 14 | B15: Rangpur (GEN-A) | C15: 17007 | D15: Mithapukur GEN-A-1 | E15: 16620 | F15: Mr. Amzad Hossain Mia | G15: 12567 | H15: Bodorgonj-2 | I15: 5623 | J15: Mr. Md. Aunar Kali | K15: Medical Information Officer | L15: 376 | M15: 105.16279 | N15: 2000 | Q15: Not Started | R15: NO
A16: 15 | B16: Rangpur (GEN-A) | C16: 17007 | D16: Rangpur GEN-A-2 | E16: 16030 | F16: Mr. Md. Wahiduzzaman Sarker | G16: 12234 | H16: Gangachora-1 | I16: 2923 | J16: Md. Hasan Sarker | K16: Sr. Medical Information Officer | L16: 372 | M16: 108.40735 | N16: 2000 | Q16: Not Started | R16: NO
A17: 16 | B17: Rangpur (GEN-A) | C17: 17007 | D17: Lalmonirhat GEN-A-1 | E17: 16033 | F17: Md. Rabiul Islam | G17: 10233 | H17: Kaligonj (Rangpur)-1 | I17: 2097 | J17: Nurul Islam | K17: Sr. Medical Information Officer | L17: 371 | M17: 127.34863 | N17: 2000 | Q17: Not Started | R17: NO
A18: 17 | B18: Dinajpur (GEN-A) | C18: 17006 | D18: Joypurhat GEN-A | E18: 16027 | F18: Mr. Md. Asadujjaman | G18: 10188 | H18: Joypurhat-2 | I18: 5986 | J18: Mr. Md. Rakib Miah | K18: Medical Information Officer | L18: 356 | M18: 102.23133 | N18: 1000 | Q18: Not Started | R18: NO
A19: 18 | B19: Faridpur (GEN-A) | C19: 17013 | D19: Faridpur GEN-A-1 | E19: 16064 | F19: Mr. Sumon Kumar Paul | G19: 11816 | H19: Faridpur-7 | I19: 1817 | J19: Md. Ashraful Islam | K19: Sr. Medical Information Officer | L19: 352 | M19: 129.62457 | N19: 2000 | Q19: Not Started | R19: NO
A20: 19 | B20: Chattogram-A (GEN-A) | C20: 17031 | D20: Chattogram GEN-A-9 | E20: 16157 | F20: Mr. Md. Zahidul Islam | G20: 11028 | H20: CTG (Navy Gate)-1 | I20: 1753 | J20: Md. Abdul Aziz | K20: Sr. Medical Information Officer | L20: 351 | M20: 119.2185 | N20: 2000 | Q20: Not Started | R20: NO
A21: 20 | B21: Chattogram-D (GEN-A) | C21: 17147 | D21: Boalkhali GEN-A-1 | E21: 16430 | F21: Mr. Md. Rezaul Hoque | G21: 13178 | H21: CTG (Rashtarmatha) | I21: 5802 | J21: Mr. Md. Helal Mahmud | K21: Medical Information Officer | L21: 350 | M21: 137.43048 | N21: 2000 | Q21: Not Started | R21: NO
A22: 21 | B22: Faridpur (GEN-A) | C22: 17013 | D22: Faridpur GEN-A-1 | E22: 16064 | F22: Mr. Sumon Kumar Paul | G22: 10430 | H22: Faridpur-3 | I22: 1826 | J22: Md. Aminul Islam | K22: Sr. Medical Information Officer | L22: 350 | M22: 106.32442 | N22: 2000 | Q22: Not Started | R22: NO
... A39: 38 | B39: Kushtia (GEN-A) | C39: 17009 | D39: Bheramara GEN-A-1 | E39: 16658 | F39: Mr. Md. Nazmul Huda | G39: 10305 | H39: Daulatpur-1 | I39: 2308 | J39: Md. Rasel Sheikhe | K39: Medical Information Officer | L39: 328 | M39: 105.4783 | N39: 2000 | Q39: Not Started | R39: NO
A40: 39 | B40: Narsingdi (GEN-A) | C40: 17016 | D40: Madhobdi GEN-A-1 | E40: 16681 | F40: Md. Mamun-Or-Rashid | G40: 10574 | H40: Madhobdi-2 | I40: 5300 | J40: Mr. Md. Muniruzzaman | K40: Sr. Medical Information Officer | L40: 327 | M40: 104.78133 | N40: 1000 | Q40: Not Started | R40: YES | S40: 10203 | T40: Rangpur-6 | U40: Rangpur GEN-A-1 | V40: Mr. Md. Shamim Hossain | W40: Rangpur
A41: 40 | B41: Cox Bazar (GEN-A) | C41: 17030 | D41: Chakaria GEN-A-1 | E41: 16159 | F41: Mr. Mohammad Nazrul Islam | G41: 11040 | H41: Chakaria-1 | I41: 1933 | J41: Ripan Saha | K41: Sr. Medical Information Officer | L41: 326 | M41: 121.94559 | N41: 2000 | Q41: Not Started | R41: NO
A42: 41 | B42: Faridpur (GEN-A) | C42: 17013 | D42: Faridpur GEN-A-1 | E42: 16064 | F42: Mr. Sumon Kumar Paul | G42: 10432 | H42: Boalmari-2 | I42: 6602 | J42: Mr. Sumon Ahmed | K42: Medical Information Officer | L42: 325 | M42: 109.47027 | N42: 2000 | Q42: Not Started | R42: NO
A43: 42 | B43: Cox Bazar (GEN-A) | C43: 17030 | D43: Keranirhat GEN-A-1 | E43: 16162 | F43: Mr. Sukrithi Rudra | G43: 11066 | H43: Satkania-1 | I43: 1475 | J43: Md. Golam Mostafa | K43: Sr. Medical Information Officer | L43: 324 | M43: 101.75365 | N43: 1000 | Q43: Not Started | R43: NO
A44: 43 | B44: Faridpur (GEN-A) | C44: 17013 | D44: Gopalgonj GEN-A-2 | E44: 16586 | F44: Mr. Provat Kumar Sarker | G44: 10441 | H44: Gopalgonj-2 | I44: 3277 | J44: Tariqul Islam | K44: Medical Information Officer | L44: 324 | M44: 108.36279 | N44: 2000 | Q44: Not Started | R44: NO
A45: 44 | B45: Chattogram-A (GEN-A) | C45: 17031 | D45: Baraiyerhat GEN-A-1 | E45: 16167 | F45: Mr. Md. Abdus Salam | G45: 11026 | H45: Ramgarh-1 | I45: 3005 | J45: Md. Ariful Islam | K45: Sr. Medical Information Officer | L45: 323 | M45: 124.19265 | N45: 2000 | Q45: Not Started | R45: NO
A46: 45 | B46: Bogura (GEN-A) | C46: 17005 | D46: Sirajgonj GEN-A-1 | E46: 16022 | F46: Md. Rabiul Alam | G46: 14541 | H46: Kamarkhanda-1 | I46: 7639 | J46: Mr. Sabbir Ahmed | K46: Medical Information Officer | L46: 321 | M46: 121.07442 | N46: 2000 | Q46: Not Started | R46: NO
A47: 46 | B47: Khulna (GEN-A) | C47: 17012 | D47: Satkhira GEN-A-2 | E47: 16063 | F47: Mr. K.M. Niaz Uddin Ahmed | G47: 10424 | H47: Kolaroa-1 | I47: 1298 | J47: Md. Khalak Molla | K47: Sr. Medical Information Officer | L47: 320 | M47: 114.31383 | N47: 2000 | Q47: Not Started | R47: NO
A48: 47 | B48: Sylhet-B (GEN-A) | C48: 17019 | D48: Bishwanath GEN-A-1 | E48: 16097 | F48: Mr. Md. Arefin Hasan | G48: 10644 | H48: Bishanath-1 | I48: 974 | J48: Md. Ziaur Rahman | K48: Sr. Medical Information Officer | L48: 320 | M48: 111.69057 | N48: 2000 | Q48: Not Started | R48: NO
A49: 48 | B49: Rangpur (GEN-A) | C49: 17007 | D49: Mithapukur GEN-A-1 | E49: 16620 | F49: Mr. Amzad Hossain Mia | G49: 12235 | H49: Mithapukur-2 | I49: 691 | J49: Md. Azizur Rahman | K49: Sr. Medical Information Officer | L49: 319 | M49: 101.81914 | N49: 1000 | Q49: Not Started | R49: NO
A50: 49 | B50: Rajshahi (GEN-A) | C50: 17008 | D50: Bagmara GEN-A-1 | E50: 16684 | F50: Mr. Md. Hasan Imam Rashel | G50: 14604 | H50: Bagmara (Rajshahi)-3 | I50: 7682 | J50: Mr. Md. Jakirul Islam | K50: Medical Information Officer | L50: 318 | M50: 129.83329 | N50: 2000 | Q50: Not Started | R50: NO
A51: 50 | B51: Rangpur (GEN-A) | C51: 17007 | D51: Rangpur GEN-A-2 | E51: 16030 | F51: Mr. Md. Wahiduzzaman Sarker | G51: 13295 | H51: Rangpur-17 | I51: 2772 | J51: Md. Saifulalm | K51: Medical Information Officer | L51: 318 | M51: 105.97032 | N51: 2000 | Q51: Not Started | R51: NO
A52: 51 | B52: Sylhet-A (GEN-A) | C52: 17018 | D52: Sylhet GEN-A-5 | E52: 16095 | F52: Md. Jakiul Islam | G52: 10626 | H52: Sylhet Popular-1 | I52: 3189 | J52: Mr. Md. Tanzidul Islam | K52: Medical Information Officer | L52: 318 | M52: 152.69929 | N52: 2000 | Q52: Not Started | R52: NO
... A150: 149 | B150: Chattogram-A (GEN-A) | C150: 17031 | D150: Sitakundu GEN-A-1 | E150: 16678 | F150: Mr. Riazul Mostafa | G150: 11092 | H150: Sitakundu-1 | I150: 3429 | J150: Mr. Rothindronath Roy | K150: Medical Information Officer | L150: 270 | M150: 103.69541 | N150: 1000 | Q150: Not Started | R150: NO
A151: 150 | B151: Cox Bazar (GEN-A) | C151: 17030 | D151: Ukhia GEN-A-1 | E151: 16533 | F151: Md. Ruhul Amin | G151: 11048 | H151: Kutupalong-1 | I151: 2135 | J151: Md. Shahadat Hossen | K151: Sr. Medical Information Officer | L151: 270 | M151: 127.24643 | N151: 2000 | Q151: Not Started | R151: YES | S151: 11139 | T151: Banshkhali-1 | U151: Banshkhali GEN-A-1 | V151: Anamul Haque | W151: Chattogram-C
A152: 151 | B152: Sylhet-B (GEN-A) | C152: 17019 | D152: Bishwanath GEN-A-1 | E152: 16097 | F152: Mr. Md. Arefin Hasan | G152: 12340 | H152: Bishanath-3 | I152: 6449 | J152: Mr. Masud Zamader | K152: Medical Information Officer | L152: 270 | M152: 111.45543 | N152: 2000 | Q152: Not Started | R152: NO
A153: 152 | B153: Barishal-B (GEN-A) | C153: 17105 | D153: Shariatpur GEN-A-1 | E153: 16069 | F153: Mr. Md. Shahadat Hossain-579 | G153: 10458 | H153: Shariatpur-2 | I153: 1427 | J153: Md. Khairul Islam | K153: Sr. Medical Information Officer | L153: 269 | M153: 110.89675 | N153: 2000 | Q153: Not Started | R153: NO
...

Sheet Award_June_2026
A1: SL | B1: Current Zone | C1: Current SAP Zone | D1: Current Region | E1: Current SAP Region | F1: Current Regional Head | G1: Current Area Code | H1: Current Area Name | I1: SAP MIO Code | J1: Sr./ MIO Name | K1: Designation | L1: No. of Rx | M1: Sales Val (Apr'26) | N1: Sales Val (Jun'26) | O1: Growth% (Jun over Apr) | P1: Award Amount (BDT) | Q1: Selected Voucher | R1: Submission Timestamp | S1: Status | T1: Is Transferred | U1: Previous Area Code | V1: Previous Area Name | W1: Previous Region | X1: Previous Regional Head | Y1: Previous Zone
A2: 1 | B2: Rajshahi (GEN-A) | C2: 17008 | D2: Rajshahi GEN-A-3 | E2: 16037 | F2: Fazlul Haque | G2: 10260 | H2: Rajshahi-12 | I2: 3275 | J2: Md. Shoriful Islam | K2: Sr. Medical Information Officer | L2: 749 | M2: 135846.83 | N2: 151079.21 | O2: 11.212908 | P2: 2000 | S2: Not Started | T2: NO
A3: 2 | B3: Rangpur (GEN-A) | C3: 17007 | D3: Lalmonirhat GEN-A-1 | E3: 16033 | F3: Md. Rabiul Islam | G3: 10233 | H3: Kaligonj (Rangpur)-1 | I3: 2097 | J3: Nurul Islam | K3: Sr. Medical Information Officer | L3: 640 | M3: 157406.16 | N3: 184902.37 | O3: 17.468319 | P3: 3000 | S3: Not Started | T3: NO
A4: 3 | B4: Dinajpur (GEN-A) | C4: 17006 | D4: Dinajpur GEN-A-2 | E4: 16026 | F4: Md. Habibur Rahman | G4: 10180 | H4: Phulbari-1 | I4: 1107 | J4: Md. Abul Hasan Mondal | K4: Sr. Medical Information Officer | L4: 637 | M4: 122563.6 | N4: 144752.47 | O4: 18.103964 | P4: 3000 | S4: Not Started | T4: NO
A5: 4 | B5: Jashore (GEN-A) | C5: 17010 | D5: Jashore GEN-A-3 | E5: 16680 | F5: Md. Mizanur Rahman | G5: 11812 | H5: Moheshpur-1 | I5: 2797 | J5: Sohidul Islam | K5: Sr. Medical Information Officer | L5: 589 | M5: 233102.99 | N5: 259804.78 | O5: 11.454932 | P5: 2000 | S5: Not Started | T5: NO
A6: 5 | B6: Chattogram-C (GEN-A) | C6: 17032 | D6: Chattogram GEN-A-10 | E6: 16326 | F6: Mr. Mohammad Ashadur Rahman | G6: 11006 | H6: CTG (National)-1 | I6: 4181 | J6: Mr. Md. Masud Rana | K6: Sr. Medical Information Officer | L6: 558 | M6: 64032.9 | N6: 195396.96 | O6: 205.15088 | P6: 3000 | S6: Not Started | T6: NO
A7: 6 | B7: Faridpur (GEN-A) | C7: 17013 | D7: Faridpur GEN-A-2 | E7: 16065 | F7: Mr. Md. Mehedi Hasan | G7: 10435 | H7: Faridpur-4 | I7: 2609 | J7: Md. Abul Basar | K7: Sr. Medical Information Officer | L7: 556 | M7: 161304.03 | N7: 195696.82 | O7: 21.321718 | P7: 3000 | S7: Not Started | T7: NO
A8: 7 | B8: Rajshahi (GEN-A) | C8: 17008 | D8: Patnitola GEN-A-1 | E8: 16038 | F8: Mr. Khondokar Mazharul Islam | G8: 14883 | H8: Porsha-1 | I8: 2605 | J8: Nandan Kumar Roy | K8: Sr. Medical Information Officer | L8: 551 | M8: 143928.38 | N8: 181019.51 | O8: 25.770546 | P8: 3000 | S8: Not Started | T8: YES | U8: 10265 | V8: Sapahar-1 | W8: Patnitola GEN-A-1 | X8: Mr. Khondokar Mazharul Islam | Y8: Rajshahi
A9: 8 | B9: Chattogram-C (GEN-A) | C9: 17032 | D9: Chattogram GEN-A-10 | E9: 16326 | F9: Mr. Mohammad Ashadur Rahman | G9: 11007 | H9: CTG (National)-2 | I9: 7404 | J9: Mr. Md. Pavel Islam | K9: Medical Information Officer | L9: 549 | M9: 95457.09 | N9: 139879.79 | O9: 46.536826 | P9: 3000 | S9: Not Started | T9: NO
A10: 9 | B10: Faridpur (GEN-A) | C10: 17013 | D10: Faridpur GEN-A-2 | E10: 16065 | F10: Mr. Md. Mehedi Hasan | G10: 10436 | H10: Faridpur-5 | I10: 8730 | J10: Mr. Md. Benjir Hossain | K10: Medical Information Officer | L10: 547 | M10: 100539.57 | N10: 119625.19 | O10: 18.983192 | P10: 3000 | S10: Not Started | T10: NO
A11: 10 | B11: Kushtia (GEN-A) | C11: 17009 | D11: Bheramara GEN-A-1 | E11: 16658 | F11: Mr. Md. Nazmul Huda | G11: 10306 | H11: Bheramara-2 | I11: 2775 | J11: Md. Shohel Rana | K11: Medical Information Officer | L11: 535 | M11: 156086.71 | N11: 197435.92 | O11: 26.491179 | P11: 3000 | S11: Not Started | T11: NO
A12: 11 | B12: Faridpur (GEN-A) | C12: 17013 | D12: Bhanga GEN-A-1 | E12: 16067 | F12: Mr. Md. Zahid Hossain Khan | G12: 10449 | H12: Nogorkanda | I12: 1166 | J12: Md. Ibrahim Dhali | K12: Sr. Medical Information Officer | L12: 534 | M12: 194032.65 | N12: 238020.57 | O12: 22.67037 | P12: 3000 | S12: Not Started | T12: NO
A13: 12 | B13: Rangpur (GEN-A) | C13: 17007 | D13: Mithapukur GEN-A-1 | E13: 16620 | F13: Mr. Amzad Hossain Mia | G13: 12567 | H13: Bodorgonj-2 | I13: 5623 | J13: Mr. Md. Aunar Kali | K13: Medical Information Officer | L13: 521 | M13: 103838 | N13: 114587.63 | O13: 10.352308 | P13: 2000 | S13: Not Started | T13: NO
A14: 13 | B14: Chattogram-D (GEN-A) | C14: 17147 | D14: Chattogram GEN-A-11 | E14: 16610 | F14: Md. Zahangir Alam | G14: 11010 | H14: CTG (Popular)-2 | I14: 1440 | J14: Md. Rokibul Islam | K14: Sr. Medical Information Officer | L14: 516 | M14: 75996.88 | N14: 101394.13 | O14: 33.418806 | P14: 3000 | S14: Not Started | T14: NO
A15: 14 | B15: Cumilla-B (GEN-A) | C15: 17093 | D15: Chandina GEN-A-1 | E15: 16145 | F15: Mr. Bishwajit Kaviraj | G15: 10950 | H15: Chandina-1 | I15: 2103 | J15: Md. Shafikul Islam | K15: Sr. Medical Information Officer | L15: 516 | M15: 191214.22 | N15: 227795.76 | O15: 19.131182 | P15: 3000 | S15: Not Started | T15: NO
A16: 15 | B16: Khulna (GEN-A) | C16: 17012 | D16: Satkhira GEN-A-2 | E16: 16063 | F16: Mr. K.M. Niaz Uddin Ahmed | G16: 10424 | H16: Kolaroa-1 | I16: 1298 | J16: Md. Khalak Molla | K16: Sr. Medical Information Officer | L16: 513 | M16: 325861.83 | N16: 415187.08 | O16: 27.412002 | P16: 3000 | S16: Not Started | T16: NO
A17: 16 | B17: Faridpur (GEN-A) | C17: 17013 | D17: Faridpur GEN-A-2 | E17: 16065 | F17: Mr. Md. Mehedi Hasan | G17: 12819 | H17: Faridpur-8 | I17: 2310 | J17: Mamunur Rashid | K17: Sr. Medical Information Officer | L17: 510 | M17: 185007.14 | N17: 224647.66 | O17: 21.426481 | P17: 3000 | S17: Not Started | T17: NO
A18: 17 | B18: Faridpur (GEN-A) | C18: 17013 | D18: Bhanga GEN-A-1 | E18: 16067 | F18: Mr. Md. Zahid Hossain Khan | G18: 10445 | H18: Bhanga-2 | I18: 3747 | J18: Mr. Md. Minhaj Perveg | K18: Sr. Medical Information Officer | L18: 505 | M18: 338875.01 | N18: 405921.55 | O18: 19.785035 | P18: 3000 | S18: Not Started | T18: NO
A19: 18 | B19: Chattogram-A (GEN-A) | C19: 17031 | D19: Chattogram GEN-A-9 | E19: 16157 | F19: Mr. Md. Zahidul Islam | G19: 13310 | H19: CTG (EPZ-3) | I19: 6164 | J19: Mr. Md. Hero Mia | K19: Medical Information Officer | L19: 490 | M19: 175217.13 | N19: 324407.1 | O19: 85.145767 | P19: 3000 | S19: Not Started | T19: NO
A20: 19 | B20: Sylhet-A (GEN-A) | C20: 17018 | D20: Sylhet GEN-A-5 | E20: 16095 | F20: Md. Jakiul Islam | G20: 10626 | H20: Sylhet Popular-1 | I20: 3189 | J20: Mr. Md. Tanzidul Islam | K20: Medical Information Officer | L20: 485 | M20: 77436.12 | N20: 98665.54 | O20: 27.415397 | P20: 3000 | S20: Not Started | T20: NO
... A194: 193 | B194: Cox Bazar (GEN-A) | C194: 17030 | D194: Keranirhat GEN-A-1 | E194: 16162 | F194: Mr. Sukrithi Rudra | G194: 11067 | H194: Satkania-2 | I194: 1607 | J194: Pabitra Kumar Sarker | K194: Sr. Medical Information Officer | L194: 346 | M194: 195157.45 | N194: 224602.69 | O194: 15.087941 | P194: 3000 | S194: Not Started | T194: NO
A195: 194 | B195: Cox Bazar (GEN-A) | C195: 17030 | D195: Ukhia GEN-A-1 | E195: 16533 | F195: Md. Ruhul Amin | G195: 11048 | H195: Kutupalong-1 | I195: 2135 | J195: Md. Shahadat Hossen | K195: Sr. Medical Information Officer | L195: 346 | M195: 164017.76 | N195: 194497.48 | O195: 18.583183 | P195: 3000 | S195: Not Started | T195: YES | U195: 11139 | V195: Banshkhali-1 | W195: Banshkhali GEN-A-1 | X195: Anamul Haque | Y195: Chattogram-C
A196: 195 | B196: Cumilla-B (GEN-A) | C196: 17093 | D196: Chandina GEN-A-2 | E196: 16694 | F196: Mr. Sk. Shafiqur Rahman | G196: 10946 | H196: Nawabpur-1 | I196: 1641 | J196: Md. Abdul Waras | K196: Sr. Medical Information Officer | L196: 345 | M196: 180584.48 | N196: 200824.37 | O196: 11.20799 | P196: 2000 | S196: Not Started | T196: NO
A197: 196 | B197: Cox Bazar (GEN-A) | C197: 17030 | D197: Chakaria GEN-A-1 | E197: 16159 | F197: Mr. Mohammad Nazrul Islam | G197: 11040 | H197: Chakaria-1 | I197: 1933 | J197: Ripan Saha | K197: Sr. Medical Information Officer | L197: 345 | M197: 193852.83 | N197: 218845.3 | O197: 12.892497 | P197: 2000 | S197: Not Started | T197: NO
A198: 197 | B198: Rangpur (GEN-A) | C198: 17007 | D198: Rangpur GEN-A-3 | E198: 16031 | F198: Mr. Raqibul Hasan | G198: 10220 | H198: Rangpur-15 | I198: 7508 | J198: Mr. Md. Shohag Ali | K198: Medical Information Officer | L198: 345 | M198: 64707.57 | N198: 85022.37 | O198: 31.394781 | P198: 3000 | S198: Not Started | T198: NO
A199: 198 | B199: Gazipur (GEN-A) | C199: 17022 | D199: Gazipur-Chowrasta GEN-A-1 | E199: 16117 | F199: Mr. Mohammad Abdul Baten | G199: 12063 | H199: Manipur | I199: 1864 | J199: Md. Milon Babu | K199: Sr. Medical Information Officer | L199: 344 | M199: 186176.8 | N199: 222638.63 | O199: 19.584519 | P199: 3000 | S199: Not Started | T199: NO
A200: 199 | B200: Chattogram-D (GEN-A) | C200: 17147 | D200: Fatikchari GEN-A-2 | E200: 16532 | F200: Md. Sumsuddoha | G200: 14076 | H200: Dighinala-1 | I200: 3427 | J200: Mr. Haritosh Chandra Das | K200: Medical Information Officer | L200: 344 | M200: 78215.78 | N200: 104317.72 | O200: 33.371706 | P200: 3000 | S200: Not Started | T200: NO
A201: 200 | B201: Chattogram-D (GEN-A) | C201: 17147 | D201: Chattogram GEN-A-11 | E201: 16610 | F201: Md. Zahangir Alam | G201: 12549 | H201: CTG (CMCH-3) | I201: 5989 | J201: Mr. Zakaria Hossain | K201: Sr. Medical Information Officer | L201: 343 | M201: 86221.71 | N201: 100809.47 | O201: 16.918894 | P201: 3000 | S201: Not Started | T201: NO
A202: 201 | B202: Chattogram-B (GEN-A) | C202: 17029 | D202: Rawjan GEN-A-1 | E202: 16429 | F202: Mr. Mohammad Jaedul Islam | G202: 13093 | H202: Rawjan-3 | I202: 5472 | J202: Mr. Md. Kamrul Hasan | K202: Sr. Medical Information Officer | L202: 343 | M202: 189489.98 | N202: 254827.24 | O202: 34.480588 | P202: 3000 | S202: Not Started | T202: NO
A203: 202 | B203: Tangail (GEN-A) | C203: 17004 | D203: Sherpur GEN-A-1 | E203: 16018 | F203: Mr. Md. Taizul Islam | G203: 11690 | H203: Nakla (Sherpur)-1 | I203: 3198 | J203: Md. Haidar Ali | K203: Sr. Medical Information Officer | L203: 343 | M203: 108050.78 | N203: 131933.78 | O203: 22.103496 | P203: 3000 | S203: Not Started | T203: NO
A204: 203 | B204: Jashore (GEN-A) | C204: 17010 | D204: Magura GEN-A-1 | E204: 16050 | F204: Mr. Md. Faisal Kabir | G204: 10338 | H204: Magura-2 | I204: 903 | J204: Shaikh Nazmul Haque | K204: Sr. Medical Information Officer | L204: 342 | M204: 172833.19 | N204: 207465.81 | O204: 20.038177 | P204: 3000 | S204: Not Started | T204: NO
A205: 204 | B205: Chattogram-D (GEN-A) | C205: 17147 | D205: Chattogram GEN-A-7 | E205: 16158 | F205: Md. Abu Naser | G205: 11011 | H205: CTG (EPIC)-2 | I205: 6163 | J205: Mr. Uzzal Ghosh | K205: Sr. Medical Information Officer | L205: 342 | M205: 127915.83 | N205: 150929.32 | O205: 17.99112 | P205: 3000 | S205: Not Started | T205: NO
A206: 205 | B206: Narsingdi (GEN-A) | C206: 17016 | D206: Kishoregonj GEN-A-2 | E206: 16086 | F206: Mr. Syed Rasel | G206: 12216 | H206: Tarail-1 | I206: 7039 | J206: Mr. Naimur Rahman | K206: Medical Information Officer | L206: 341 | M206: 139070.16 | N206: 189654.82 | O206: 36.373482 | P206: 3000 | S206: Not Started | T206: NO
A207: 206 | B207: Dhaka-B (GEN-A) | C207: 17017 | D207: Dhaka GEN-A-2 | E207: 16088 | F207: Mr. Md. Arif Sarkar | G207: 10581 | H207: BIRDEM-Eskaton | I207: 2746 | J207: Pritom Biswas | K207: Sr. Medical Information Officer | L207: 341 | M207: 49700.26 | N207: 59085.64 | O207: 18.883966 | P207: 3000 | S207: Not Started | T207: NO
... A275: 274 | B275: Chattogram-B (GEN-A) | C275: 17029 | D275: Chandraghona GEN-A-1 | E275: 16168 | F275: Mr. Md. Zakir Hossain | G275: 11103 | H275: Rangunia-1 | I275: 809 | J275: Gobinda Chandra Sarkar | K275: Sr. Medical Information Officer | L275: 318 | M275: 315906.52 | N275: 353867.49 | O275: 12.01652 | P275: 2000 | S275: Not Started | T275: NO
A276: 275 | B276: Rangpur (GEN-A) | C276: 17007 | D276: Rangpur GEN-A-3 | E276: 16031 | F276: Mr. Raqibul Hasan | G276: 13192 | H276: Rangpur-14 | I276: 927 | J276: Md. Masum Billah | K276: Sr. Medical Information Officer | L276: 318 | M276: 167435.99 | N276: 184452.45 | O276: 10.162964 | P276: 2000 | S276: Not Started | T276: YES | U276: 10634 | V276: Chattak-2 | W276: Sylhet GEN-A-1 | X276: Mr. Md. Golam Sarwar | Y276: Sylhet-A
A277: 276 | B277: Gazipur (GEN-A) | C277: 17022 | D277: Konabari GEN-A-1 | E277: 16115 | F277: Md. Abdul Hye Al Hadi | G277: 10755 | H277: Konabari-Kashimpur | I277: 1322 | J277: Mr. Ruhul Kudus | K277: Sr. Medical Information Officer | L277: 318 | M277: 162773.26 | N277: 188185.45 | O277: 15.612018 | P277: 3000 | S277: Not Started | T277: NO
A278: 277 | B278: Chattogram-B (GEN-A) | C278: 17029 | D278: Chattogram GEN-A-5 | E278: 16164 | F278: Mr. Md. Ziaur Rahman | G278: 13107 | H278: CTG (Aturar Depot)-2 | I278: 7302 | J278: Mr. Lakkhon Kumar Roy | K278: Medical Information Officer | L278: 318 | M278: 291213.93 | N278: 322428.31 | O278: 10.718711 | P278: 2000 | S278: Not Started | T278: NO
A279: 278 | B279: Rajshahi (GEN-A) | C279: 17008 | D279: Chapainwabgonj GEN-A-1 | E279: 16040 | F279: Mr. Md. Enamul Haque | G279: 10278 | H279: C.Nawabganj-3 | I279: 1722 | J279: Md. Mamunur Rashid | K279: Sr. Medical Information Officer | L279: 317 | M279: 109040.32 | N279: 128770.51 | O279: 18.094398 | P279: 3000 | S279: Not Started | T279: NO
A280: 279 | B280: Mymensingh (GEN-A) | C280: 17024 | D280: Netrokona GEN-A-1 | E280: 16130 | F280: Mr. Muhammad Zakir Hossain | G280: 14646 | H280: Netrokona-5 | I280: 8306 | J280: Mr. Pobetro Kumar Ray | K280: Medical Information Officer | L280: 317 | M280: 131933.83 | N280: 162938.27 | O280: 23.499992 | P280: 3000 | S280: Not Started | T280: NO
...
